Workbook

Sheet Empezar aqui
B2: Empezar de nuevo, bien
B3: Plantilla para registrar tu foto financiera de hoy y cargarla en la app.
B5: Como funciona
B6: 1. Llena las hojas 1 a 8. Solo las celdas amarillas.
B7: 2. Me devuelves el archivo.
B8: 3. Yo lo convierto en una copia de respaldo (.json) y te la paso.
B9: 4. En la app: Ajustes > Copias y datos > Restaurar copia (JSON). Reemplaza todo lo que haya.
B10: Desde ahi en adelante anotas en la app y la bandeja del banco te ayuda sola.
B12: Las dos reglas de esta plantilla
B13: Amarillo = lo llenas tu. Gris = lo calcula la hoja, no lo toques.
B14: Las filas en gris cursiva son EJEMPLOS: borralas antes de devolverme el archivo.
B16: Lo mas importante: pon saldos y deudas de HOY, no los originales
... B33: El lector de correos del banco reconoce la cuenta o tarjeta por su NOMBRE. Si le cambias el nombre a las filas que ya vienen escritas, la bandeja deja de asignarlas sola y te va a tocar elegir a mano cada vez. Puedes agregar las que quieras, eso no rompe nada.

Sheet 1 Perfil
A1: 1. Tu perfil
A2: De aqui sale tu sueldo neto y el objetivo 50/30/20.
A4: Dato | B4: Valor | C4: Para que sirve / que poner
A5: Tu nombre | B5: Jordan | C5: Sale en el estado de cuenta mensual.
A6: Fecha de corte | B6: 2026-09-30 | C6: Los saldos de la hoja 2 son a esta fecha. Dejala asi para arrancar limpio en octubre.
A7: Sueldo bruto mensual (S/) | B7: 3500 | C7: Lo que dice tu boleta ANTES de descuentos.
A8: Aporte AFP (%) | B8: 0.1 | C8: Lo tipico es 10%. Revisa tu boleta.
A9: Comision AFP (%) | B9: 0.0155 | C9: Depende de tu AFP. Si no sabes, deja el valor que viene.
A10: Prima de seguro AFP (%) | B10: 0.0135 | C10: Igual: si no sabes, dejalo.
A11: Otros descuentos fijos (S/) | B11: 78.56 | C11: Quinta categoria, prestamo descontado por planilla, etc.
A12: Otros ingresos fijos (S/) | B12: 0 | C12: Algo que entra todos los meses aparte del sueldo.
A13: Te pagan en quincenas? | B13: Si | C13: Si o No.
A14: Quincena 1 - dia 15 (S/) | B14: 1484.97 | C14: Lo que te cae a mitad de mes. Si cae sabado, domingo o feriado la app lo adelanta sola.
A15: Quincena 2 - fin de mes (S/) | B15: 1484.97 | C15: Lo que te cae a fin de mes.
A16: Cuenta donde cae el sueldo | B16: Cuenta Sueldo BCP | C16: Escribela igual que en la hoja 2 Cuentas.
A18: Sueldo neto estimado (S/) | B18: =IFERROR(B7-(B7*(B8+B9+B10)+B11),0) -> 2969.94 | C18: Bruto menos AFP y otros descuentos. Es la misma formula que usa la app.
A19: Ingreso mensual total (S/) | B19: =IFERROR(B18+B12,0) -> 2969.94 | C19: Neto + otros ingresos. Sobre este numero se reparte el 50/30/20.
A21: Tu neto real son 2,969.94 (tus dos quincenas). Con bruto 3,500 y la AFP al 12.9% salian 3,048.50, asi que los 78.56 que sobraban van como 'otros descuentos'. Si en tu boleta ves de que es ese descuento, dimelo y lo nombramos bien.

Sheet 2 Cuentas
A1: 2. Donde tienes plata hoy
A2: Entra a cada banco y copia el saldo tal como esta. Sin redondear.
A4: Nombre de la cuenta | B4: Saldo hoy (S/) | C4: Para que la usas (opcional)
A5: Efectivo | B5: 350 | C5: Emergencia
A6: Cuenta BCP / Yape | B6: 238.92 | C6: Compras
A7: Cuenta Sueldo BCP | B7: 108.71 | C7: Sueldo
A8: Wardadito BCP | B8: 1200 | C8: Ahorro
A9: Cuenta Interbank / Plin | B9: 233.84 | C9: Compras
A10: Caja Huancayo | B10: 9500 | C10: Emergencia
A11: Ripley Max | B11: 20 | C11: Compras
A28: Total que tienes hoy | B28: =SUM(B5:B27) -> 11651.47
A30: Los seis nombres que ya vienen escritos son los que el lector de correos reconoce solo. Si no usas alguno, borra la fila.
A31: Si una cuenta esta en dolares, escribelo en la ultima columna y pon el saldo en dolares: yo lo convierto y te digo con que tipo de cambio.
A32: Los wardaditos van aparte, como los tienes. No los sumes aqui si no quieres verlos como disponible.

Sheet 3 Tarjetas
A1: 3. Tus tarjetas de credito
A2: Solo los datos de la tarjeta. Las cuotas van en la hoja 4.
A4: Nombre de la tarjeta | B4: Linea de credito (S/) | C4: Dia de pago | D4: Dia de cierre | E4: Pago minimo (S/) | F4: Ultimos 4 digitos (opcional)
A5: Tarjeta BCP | B5: 10700 | C5: 20 | D5: 25 | F5: 1973
A6: Tarjeta Interbank | B6: 3750 | C6: 20 | D6: 31 | F6: 141
A17: Dia de cierre = el dia en que el banco corta el mes. BCP suele ser 25; Interbank, fin de mes (pon 31).
A18: Dia de pago = la fecha limite que aparece en tu estado de cuenta.
A19: Pago minimo: si no lo tienes a mano dejalo vacio, no rompe nada.
A20: Mantener 'BCP' y 'Interbank' en el nombre es lo que permite que la bandeja de correos las reconozca.

Sheet 4 Cuotas tarjeta
A1: 4. Lo que sigues pagando con tarjeta
A2: Una fila por compra en cuotas. Lo que FALTA, no el precio original.
A4: Tarjeta | B4: Que compraste | C4: Saldo que falta (S/) | D4: Cuotas que faltan | E4: TEA (%) | F4: Mes de la proxima cuota (1-12) | G4: Ano | H4: Cuota mensual (calculada)
A5: Tarjeta BCP | B5: General - inicio 1 | C5: 2750 | D5: 1 | E5: 0 | F5: 10 | G5: 2026 | H5: =IFERROR(IF(OR($C5="",$D5="",$D5=0),"",IF(N($E5)>0,$C5*((1+$E5)^(1/12)-1)/(1-(1+((1+$E5)^(1/12)-1))^(-$D5)),$C5/$D5)),"") -> 2750
A6: Tarjeta BCP | B6: General - inicio 2 | C6: 4650 | D6: 3 | E6: 0 | F6: 10 | G6: 2026 | H6: =IFERROR(IF(OR($C6="",$D6="",$D6=0),"",IF(N($E6)>0,$C6*((1+$E6)^(1/12)-1)/(1-(1+((1+$E6)^(1/12)-1))^(-$D6)),$C6/$D6)),"") -> 1550
A7: Tarjeta Interbank | B7: General - inicio 1 | C7: 413 | D7: 1 | E7: 0 | F7: 10 | G7: 2026 | H7: =IFERROR(IF(OR($C7="",$D7="",$D7=0),"",IF(N($E7)>0,$C7*((1+$E7)^(1/12)-1)/(1-(1+((1+$E7)^(1/12)-1))^(-$D7)),$C7/$D7)),"") -> 413
A8: Tarjeta Interbank | B8: General - inicio 2 | C8: 2000 | D8: 2 | E8: 0 | F8: 10 | G8: 2026 | H8: =IFERROR(IF(OR($C8="",$D8="",$D8=0),"",IF(N($E8)>0,$C8*((1+$E8)^(1/12)-1)/(1-(1+((1+$E8)^(1/12)-1))^(-$D8)),$C8/$D8)),"") -> 1000
H9: =IFERROR(IF(OR($C9="",$D9="",$D9=0),"",IF(N($E9)>0,$C9*((1+$E9)^(1/12)-1)/(1-(1+((1+$E9)^(1/12)-1))^(-$D9)),$C9/$D9)),"")
H10: =IFERROR(IF(OR($C10="",$D10="",$D10=0),"",IF(N($E10)>0,$C10*((1+$E10)^(1/12)-1)/(1-(1+((1+$E10)^(1/12)-1))^(-$D10)),$C10/$D10)),"")
H11: =IFERROR(IF(OR($C11="",$D11="",$D11=0),"",IF(N($E11)>0,$C11*((1+$E11)^(1/12)-1)/(1-(1+((1+$E11)^(1/12)-1))^(-$D11)),$C11/$D11)),"")
H12: =IFERROR(IF(OR($C12="",$D12="",$D12=0),"",IF(N($E12)>0,$C12*((1+$E12)^(1/12)-1)/(1-(1+((1+$E12)^(1/12)-1))^(-$D12)),$C12/$D12)),"")
H13: =IFERROR(IF(OR($C13="",$D13="",$D13=0),"",IF(N($E13)>0,$C13*((1+$E13)^(1/12)-1)/(1-(1+((1+$E13)^(1/12)-1))^(-$D13)),$C13/$D13)),"")
H14: =IFERROR(IF(OR($C14="",$D14="",$D14=0),"",IF(N($E14)>0,$C14*((1+$E14)^(1/12)-1)/(1-(1+((1+$E14)^(1/12)-1))^(-$D14)),$C14/$D14)),"")
H15: =IFERROR(IF(OR($C15="",$D15="",$D15=0),"",IF(N($E15)>0,$C15*((1+$E15)^(1/12)-1)/(1-(1+((1+$E15)^(1/12)-1))^(-$D15)),$C15/$D15)),"")
H16: =IFERROR(IF(OR($C16="",$D16="",$D16=0),"",IF(N($E16)>0,$C16*((1+$E16)^(1/12)-1)/(1-(1+((1+$E16)^(1/12)-1))^(-$D16)),$C16/$D16)),"")
H17: =IFERROR(IF(OR($C17="",$D17="",$D17=0),"",IF(N($E17)>0,$C17*((1+$E17)^(1/12)-1)/(1-(1+((1+$E17)^(1/12)-1))^(-$D17)),$C17/$D17)),"")
H18: =IFERROR(IF(OR($C18="",$D18="",$D18=0),"",IF(N($E18)>0,$C18*((1+$E18)^(1/12)-1)/(1-(1+((1+$E18)^(1/12)-1))^(-$D18)),$C18/$D18)),"")
H19: =IFERROR(IF(OR($C19="",$D19="",$D19=0),"",IF(N($E19)>0,$C19*((1+$E19)^(1/12)-1)/(1-(1+((1+$E19)^(1/12)-1))^(-$D19)),$C19/$D19)),"")
H20: =IFERROR(IF(OR($C20="",$D20="",$D20=0),"",IF(N($E20)>0,$C20*((1+$E20)^(1/12)-1)/(1-(1+((1+$E20)^(1/12)-1))^(-$D20)),$C20/$D20)),"")
... H26: =IFERROR(IF(OR($C26="",$D26="",$D26=0),"",IF(N($E26)>0,$C26*((1+$E26)^(1/12)-1)/(1-(1+((1+$E26)^(1/12)-1))^(-$D26)),$C26/$D26)),"")
A27: Total deuda en cuotas | C27: =SUM(C5:C26) -> 9813 | H27: =SUM(H5:H26) -> 5713
A29: Borra la fila del ejemplo en gris.
A30: Si usaste la tarjeta y lo vas a pagar de un solo golpe, ponlo igual: cuotas que faltan = 1.
A31: TEA: si la compra fue sin intereses pon 0%. Si no sabes, pon 0% y dime, y lo ajustamos despues.
A32: Mes de la proxima cuota: el mes en que te cobran la siguiente, no cuando compraste.
A33: La ultima columna es solo para que verifiques: si no te cuadra con tu estado de cuenta, avisame.

Sheet 5 Prestamos
A1: 5. Tus prestamos
A2: Otra vez: lo que FALTA pagar, no lo que te prestaron.
A4: Nombre del prestamo | B4: Saldo pendiente hoy (S/) | C4: Cuota mensual (S/) | D4: Cuotas que faltan | E4: Dia de pago | F4: Mes de la proxima cuota (1-12) | G4: Ano
A5: Prestamo Caja Huancayo | B5: 20000 | C5: 1200 | D5: 17 | E5: 15 | F5: 10 | G5: 2026
A6: Prestamo BCP | B6: 11500 | C6: 447.95 | D6: 59 | E6: 1 | F6: 10 | G6: 2026
A7: Prestamo BCP | B7: 14500 | C7: 534 | D7: 58 | E7: 15 | F7: 10 | G7: 2026
A8: Prestamo BCP | B8: 2684.56 | C8: 266.42 | D8: 12 | E8: 30 | F8: 10 | G8: 2026
A9: Prestamo Ripley | B9: 1000 | C9: 210 | D9: 5 | E9: 29 | F9: 10 | G9: 2026
A19: Total que debes | B19: =SUM(B5:B18) -> 49684.56 | C19: =SUM(C5:C18) -> 2658.37
A21: Borra la fila del ejemplo en gris.
A22: Si el nombre lleva 'Huancayo' o 'Ripley', cuando llegue el correo de ese pago la app te propone abonarlo a ESA deuda sola.
A23: Si no sabes el saldo exacto, pon cuota x cuotas que faltan y marcalo: sera una estimacion y te lo voy a decir asi.

Sheet 6 Cargos fijos
A1: 6. Lo que se repite todos los meses
A2: La app los va cargando sola cada mes para que no se te olviden.
A4: Concepto | B4: Categoria | C4: Monto (S/) | D4: Dia del mes | E4: De que cuenta sale
A5: iCloud | B5: Servicios (luz, agua, internet, cel) | C5: 45 | D5: 5 | E5: Cuenta Sueldo BCP
A6: Claro | B6: Servicios (luz, agua, internet, cel) | C6: 50 | D6: 10 | E6: Cuenta Sueldo BCP
A7: Movistar | B7: Servicios (luz, agua, internet, cel) | C7: 80 | D7: 15 | E7: Cuenta Sueldo BCP
A27: Total fijo al mes | C27: =SUM(C5:C26) -> 175
A29: Sale de tu Excel de gastos (GASTO FIJO): iCloud 45, Claro 50, Movistar 80. Total 175 al mes.
A30: Lo que yo puse a ojo y tienes que corregir: el dia de cobro de cada uno (5, 10 y 15) y que los tres salgan de la Cuenta Sueldo BCP.
A31: El 'BCP 260' de tu Excel no esta aqui: es el prestamo BCP de 266.42 que ya pusiste en la hoja 5. Ponerlo dos veces te duplicaria el gasto.
A32: No pongas aqui las cuotas de tarjeta ni los prestamos: ya estan en las hojas 4 y 5.

Sheet 7 Presupuesto
A1: 7. Cuanto quieres gastar al mes
A2: Estas son las categorias que ya trae la app. Pon un limite a las que uses.
A4: Categoria | B4: Grupo | C4: Limite al mes (S/) | D4: Comentario (opcional)
A5: Alimentacion | B5: Necesidad | C5: 750 | D5: Tu Excel: 750 al mes todo 2027 (25 al dia).
A6: Transporte | B6: Necesidad | C6: 150 | D6: Tu Excel: 150 al mes.
A7: Servicios (luz, agua, internet, cel) | B7: Necesidad | C7: 175 | D7: iCloud 45 + Claro 50 + Movistar 80, igual que la hoja 6.
A8: Vivienda / Alquiler | B8: Necesidad | C8: 0 | D8: No tienes alquiler en tu Excel.
A9: Salud | B9: Necesidad | C9: 0 | D9: Tu Excel no tiene nada de salud. Si gastas en farmacia, ponle un limite.
A10: Pago de deudas | B10: Deuda | C10: 0 | D10: Dejalo en cero: la app lo pone sola igual a las cuotas del mes.
A11: Gym / Deporte | B11: Gusto | C11: 200 | D11: Tu Excel: 200 al mes desde enero 2027 (en 2026 estaba en cero).
A12: Restaurantes / Salidas | B12: Gusto | C12: 0 | D12: Tu Excel no lo separa. Si quieres verlo aparte, sacale plata a Alimentacion u Otros.
A13: Entretenimiento | B13: Gusto | C13: 0 | D13: Tu Excel no lo tiene. Streaming y salidas estan dentro de Otros.
A14: Ropa | B14: Gusto | C14: 150 | D14: Tu Excel: 300 cada dos meses = 150 al mes en promedio. Si prefieres que no te marque exceso el mes que compras, sube a 300.
A15: Otros | B15: Gusto | C15: 300 | D15: Tu Excel: 300 al mes.
A16: Ahorro / Fondo | B16: Ahorro | C16: 0 | D16: En cero a proposito: con tus cuotas de hoy no sobra para ahorrar.
A17: Aporte a metas | B17: Ahorro | C17: 0 | D17: En cero por lo mismo.
A18: Total asignado | C18: =SUM(C5:C17) -> 1725
A20: Objetivo 50/30/20 sobre tu ingreso
A21: Grupo | B21: Objetivo (S/) | C21: Lo que asignaste (S/) | D21: Diferencia (S/)
A22: Necesidades (50%) | B22: =IFERROR('1 Perfil'!$B$19*0.5,0) -> 1484.97 | C22: =SUMIF($B$5:$B$17,"Necesidad",$C$5:$C$17) -> 1075 | D22: =C22-B22 -> -409.97
A23: Gustos (30%) | B23: =IFERROR('1 Perfil'!$B$19*0.3,0) -> 890.982 | C23: =SUMIF($B$5:$B$17,"Gusto",$C$5:$C$17) -> 650 | D23: =C23-B23 -> -240.982
A24: Ahorro y deuda (20%) | B24: =IFERROR('1 Perfil'!$B$19*0.2,0) -> 593.988 | C24: =SUMIF($B$5:$B$17,"Ahorro",$C$5:$C$17)+SUMIF($B$5:$B$17,"Deuda",$C$5:$C$17) -> 0 | D24: =C24-B24 -> -593.988
A26: El objetivo sale de tu ingreso mensual de la hoja 1 Perfil. Si esa hoja esta vacia, aqui vas a ver ceros.
A27: La diferencia en positivo significa que estas asignando mas de lo que recomienda la regla. No es un error, es un dato.
A28: Pago de deudas no necesita limite: la app lo pone sola igual a las cuotas del mes.
A30: Lo que entra y lo que sale, con tus numeros
A31: Concepto | B31: Monto (S/)
A32: Lo que te cae al mes (tus dos quincenas) | B32: ='1 Perfil'!$B$14+'1 Perfil'!$B$15 -> 2969.94 | C32: 2,969.94. Es tu neto real, confirmado por ti.
A33: Lo que cuesta vivir al mes | B33: =$C$18 -> 1725 | C33: El total de limites de arriba.
A34: Cuotas de tarjeta de octubre 2026 | B34: ='4 Cuotas tarjeta'!$H$27 -> 5713 | C34: Las cuatro compras de la hoja 4 arrancan en octubre, asi que todas caen este mes.
A35: Cuotas de prestamos al mes | B35: ='5 Prestamos'!$C$19 -> 2658.37 | C35: Los cinco prestamos de la hoja 5.
A36: Total a pagar en octubre 2026 | B36: =B33+B34+B35 -> 10096.37 | C36: Vivir + tarjetas + prestamos.
A37: Te falta en octubre | B37: =B32-B36 -> -7126.43 | C37: Lo tendrias que sacar de tus cuentas o de la Caja Huancayo.
A38: Cuotas de tarjeta de noviembre 2026 | B38: 2550 | C38: Las dos compras que siguen vivas: BCP 1,550 + Interbank 1,000. Puesto a mano, no sale de una formula.
A39: Viaje a Argentina (una sola vez) | B39: 2500 | C39: Lo que falta del viaje. El pasaje de 2,500 ya lo pagaste, asi que no se cuenta otra vez.
A40: Total a pagar en noviembre 2026 | B40: =B33+B38+B35+B39 -> 9433.37 | C40: Vivir + tarjetas + prestamos + viaje.
A41: Te falta en noviembre | B41: =B32-B40 -> -6463.43 | C41: El mes mas caro de los dos.
A42: Total a pagar desde enero 2027 | B42: =B33+B35 -> 4383.37 | C42: En enero ya no quedan cuotas de tarjeta: solo prestamos.
A43: Te falta cada mes desde enero 2027 | B43: =B32-B42 -> -1413.43 | C43: Este es el hueco de fondo, el que no se arregla solo hasta marzo de 2028.
A44: Grati + CTS + bono, repartido por mes | B44: =14000/12 -> 1166.6667 | C44: De tu Excel 2027: grati 3,500 x2, CTS 1,750 x2, bono 3,500 = 14,000 al ano.
...

Sheet 8 Metas
A1: 8. Para que estas ahorrando
A2: Si no tienes ninguna, deja la hoja vacia.
A4: Nombre de la meta | B4: Cuanto necesitas (S/) | C4: Cuanto tienes ya (S/) | D4: Para cuando (AAAA-MM-DD)
A5: Viaje a Argentina | B5: 2500 | C5: 0 | D5: 2026-11-30
A6: Fondo de emergencia | B6: 5175 | C6: 9500 | D6: 2027-12-31
A19: Viaje a Argentina: 2,500 para noviembre. El pasaje de 2,500 ya lo pagaste, asi que aqui va solo lo que falta.
A20: Fondo de emergencia: objetivo 5,175 = tres meses de lo que cuesta vivir (1,725 x 3). Los 9,500 son la Caja Huancayo que marcaste como Emergencia, asi que la app la va a mostrar cumplida: sirve como el piso que no quieres bajar.
A21: El Wardadito BCP de 1,200 queda como disponible, como pediste.
A22: El Wardadito BCP de 1,200 lo dejaste en la hoja 2, asi que la app lo va a contar como disponible. Si no quieres verlo asi, avisame y lo saco.
